<!DOCTYPE html>
<html lang=zh>
<head>
    <!-- so meta -->
    <meta charset="utf-8">
    <meta http-equiv="X-UA-Compatible" content="IE=edge">
    <meta name="HandheldFriendly" content="True">
    <meta name="viewport" content="width=device-width, initial-scale=1, maximum-scale=1" />
    <meta name="description" content="错误、调试和测试在程序运行过程中，总会遇到各种各样的错误。 有的错误是程序编写有问题造成的，比如本来应该输出整数结果输出了字符串，这种错误我们通常称之为bug，bug是必须修复的。 有的错误是用户输入造成的，比如让用户输入email地址，结果得到一个空字符串，这种错误可以通过检查用户输入来做相应的处理。 还有一类错误是完全无法在程序运行过程中预测的，比如写入文件的时候，磁盘满了，写不进去了，或者从">
<meta name="keywords" content="python">
<meta property="og:type" content="article">
<meta property="og:title" content="Python错误调试及IO编程">
<meta property="og:url" content="http://yoursite.com/2018/02/22/Python错误调试及IO编程.html">
<meta property="og:site_name" content="BirdMichael">
<meta property="og:description" content="错误、调试和测试在程序运行过程中，总会遇到各种各样的错误。 有的错误是程序编写有问题造成的，比如本来应该输出整数结果输出了字符串，这种错误我们通常称之为bug，bug是必须修复的。 有的错误是用户输入造成的，比如让用户输入email地址，结果得到一个空字符串，这种错误可以通过检查用户输入来做相应的处理。 还有一类错误是完全无法在程序运行过程中预测的，比如写入文件的时候，磁盘满了，写不进去了，或者从">
<meta property="og:locale" content="zh-CN">
<meta property="og:updated_time" content="2018-02-26T02:19:38.000Z">
<meta name="twitter:card" content="summary">
<meta name="twitter:title" content="Python错误调试及IO编程">
<meta name="twitter:description" content="错误、调试和测试在程序运行过程中，总会遇到各种各样的错误。 有的错误是程序编写有问题造成的，比如本来应该输出整数结果输出了字符串，这种错误我们通常称之为bug，bug是必须修复的。 有的错误是用户输入造成的，比如让用户输入email地址，结果得到一个空字符串，这种错误可以通过检查用户输入来做相应的处理。 还有一类错误是完全无法在程序运行过程中预测的，比如写入文件的时候，磁盘满了，写不进去了，或者从">
    
    
        
          
              <link rel="shortcut icon" href="/images/favicon.ico">
          
        
        
          
            <link rel="icon" type="image/png" href="/images/favicon-192x192.png" sizes="192x192">
          
        
        
          
            <link rel="apple-touch-icon" sizes="180x180" href="/images/apple-touch-icon.png">
          
        
    
    <!-- title -->
    <title>Python错误调试及IO编程</title>
    <!-- styles -->
    <link rel="stylesheet" href="/css/style.css">
    <!-- persian styles -->
    
      <link rel="stylesheet" href="/css/rtl.css">
    
    <!-- rss -->
    
    
</head>

<body class="max-width mx-auto px3 ltr">
    
      <div id="header-post">
  <a id="menu-icon" href="#"><i class="fas fa-bars fa-lg"></i></a>
  <a id="menu-icon-tablet" href="#"><i class="fas fa-bars fa-lg"></i></a>
  <a id="top-icon-tablet" href="#" onclick="$('html, body').animate({ scrollTop: 0 }, 'fast');" style="display:none;"><i class="fas fa-chevron-up fa-lg"></i></a>
  <span id="menu">
    <span id="nav">
      <ul>
        
      </ul>
    </span>
    <br/>
    <span id="actions">
      <ul>
        
        <li><a class="icon" href="/2018/12/04/BMMusicPlayer播放器。仿网易云转动音效.html"><i class="fas fa-chevron-left" aria-hidden="true" onmouseover="$('#i-prev').toggle();" onmouseout="$('#i-prev').toggle();"></i></a></li>
        
        
        <li><a class="icon" href="/2018/02/06/Python问题采样.html"><i class="fas fa-chevron-right" aria-hidden="true" onmouseover="$('#i-next').toggle();" onmouseout="$('#i-next').toggle();"></i></a></li>
        
        <li><a class="icon" href="#" onclick="$('html, body').animate({ scrollTop: 0 }, 'fast');"><i class="fas fa-chevron-up" aria-hidden="true" onmouseover="$('#i-top').toggle();" onmouseout="$('#i-top').toggle();"></i></a></li>
        <li><a class="icon" href=/ ><i class="fa fa-home" aria-hidden="true" onmouseover="$('#i-home').toggle();" onmouseout="$('#i-home').toggle();"></i></a></li>
      </ul>
      <span id="i-home" class="info" style="display:none;">首 页</span>
      <span id="i-prev" class="info" style="display:none;">上一篇</span>
      <span id="i-next" class="info" style="display:none;">下一篇</span>
      <span id="i-top" class="info" style="display:none;">返回顶部</span>
    </span>
    <br/>
    <div id="share" style="display: none">
      <ul>
  <li><a class="icon" href="http://www.facebook.com/sharer.php?u=http://yoursite.com/2018/02/22/Python错误调试及IO编程.html"><i class="fab fa-facebook " aria-hidden="true"></i></a></li>
  <li><a class="icon" href="https://twitter.com/share?url=http://yoursite.com/2018/02/22/Python错误调试及IO编程.html&text=Python错误调试及IO编程"><i class="fab fa-twitter " aria-hidden="true"></i></a></li>
  <li><a class="icon" href="http://www.linkedin.com/shareArticle?url=http://yoursite.com/2018/02/22/Python错误调试及IO编程.html&title=Python错误调试及IO编程"><i class="fab fa-linkedin " aria-hidden="true"></i></a></li>
  <li><a class="icon" href="https://pinterest.com/pin/create/bookmarklet/?url=http://yoursite.com/2018/02/22/Python错误调试及IO编程.html&is_video=false&description=Python错误调试及IO编程"><i class="fab fa-pinterest " aria-hidden="true"></i></a></li>
  <li><a class="icon" href="mailto:?subject=Python错误调试及IO编程&body=Check out this article: http://yoursite.com/2018/02/22/Python错误调试及IO编程.html"><i class="fas fa-envelope " aria-hidden="true"></i></a></li>
  <li><a class="icon" href="https://getpocket.com/save?url=http://yoursite.com/2018/02/22/Python错误调试及IO编程.html&title=Python错误调试及IO编程"><i class="fab fa-get-pocket " aria-hidden="true"></i></a></li>
  <li><a class="icon" href="http://reddit.com/submit?url=http://yoursite.com/2018/02/22/Python错误调试及IO编程.html&title=Python错误调试及IO编程"><i class="fab fa-reddit " aria-hidden="true"></i></a></li>
  <li><a class="icon" href="http://www.stumbleupon.com/submit?url=http://yoursite.com/2018/02/22/Python错误调试及IO编程.html&title=Python错误调试及IO编程"><i class="fab fa-stumbleupon " aria-hidden="true"></i></a></li>
  <li><a class="icon" href="http://digg.com/submit?url=http://yoursite.com/2018/02/22/Python错误调试及IO编程.html&title=Python错误调试及IO编程"><i class="fab fa-digg " aria-hidden="true"></i></a></li>
  <li><a class="icon" href="http://www.tumblr.com/share/link?url=http://yoursite.com/2018/02/22/Python错误调试及IO编程.html&name=Python错误调试及IO编程&description="><i class="fab fa-tumblr " aria-hidden="true"></i></a></li>
</ul>

    </div>
    <div id="toc">
      <ol class="toc"><li class="toc-item toc-level-1"><a class="toc-link" href="#错误、调试和测试"><span class="toc-number">1.</span> <span class="toc-text">错误、调试和测试</span></a><ol class="toc-child"><li class="toc-item toc-level-2"><a class="toc-link" href="#错误处理"><span class="toc-number">1.1.</span> <span class="toc-text">错误处理</span></a><ol class="toc-child"><li class="toc-item toc-level-3"><a class="toc-link" href="#try"><span class="toc-number">1.1.1.</span> <span class="toc-text">try</span></a></li><li class="toc-item toc-level-3"><a class="toc-link" href="#调用栈"><span class="toc-number">1.1.2.</span> <span class="toc-text">调用栈</span></a></li><li class="toc-item toc-level-3"><a class="toc-link" href="#记录错误"><span class="toc-number">1.1.3.</span> <span class="toc-text">记录错误</span></a></li><li class="toc-item toc-level-3"><a class="toc-link" href="#抛出错误"><span class="toc-number">1.1.4.</span> <span class="toc-text">抛出错误</span></a></li></ol></li></ol></li></ol>
    </div>
  </span>
</div>

    
    <div class="content index py4">
        
        <article class="post" itemscope itemtype="http://schema.org/BlogPosting">
  <header>
    
    <h1 class="posttitle" itemprop="name headline">
        Python错误调试及IO编程
    </h1>



    <div class="meta">
      <span class="author" itemprop="author" itemscope itemtype="http://schema.org/Person">
        <span itemprop="name">BirdMichael</span>
      </span>
      
    <div class="postdate">
        <time datetime="2018-02-22T02:44:41.000Z" itemprop="datePublished">2018-02-22</time>
    </div>


      
    <div class="article-category">
        <i class="fas fa-archive"></i>
        <a class="category-link" href="/categories/python/">python</a>
    </div>


      
    <div class="article-tag">
        <i class="fas fa-tag"></i>
        <a class="tag-link" href="/tags/python/">python</a>
    </div>


    </div>
  </header>
  

  <div class="content" itemprop="articleBody">
    <h1 id="错误、调试和测试"><a href="#错误、调试和测试" class="headerlink" title="错误、调试和测试"></a>错误、调试和测试</h1><p>在程序运行过程中，总会遇到各种各样的错误。</p>
<p>有的错误是程序编写有问题造成的，比如本来应该输出整数结果输出了字符串，这种错误我们通常称之为bug，bug是必须修复的。</p>
<p>有的错误是用户输入造成的，比如让用户输入email地址，结果得到一个空字符串，这种错误可以通过检查用户输入来做相应的处理。</p>
<p>还有一类错误是完全无法在程序运行过程中预测的，比如写入文件的时候，磁盘满了，写不进去了，或者从网络抓取数据，网络突然断掉了。这类错误也称为异常，在程序中通常是必须处理的，否则，程序会因为各种问题终止并退出。</p>
<p>Python内置了一套异常处理机制，来帮助我们进行错误处理。</p>
<p>此外，我们也需要跟踪程序的执行，查看变量的值是否正确，这个过程称为调试。Python的pdb可以让我们以单步方式执行代码。</p>
<p>最后，编写测试也很重要。有了良好的测试，就可以在程序修改后反复运行，确保程序输出符合我们编写的测试。</p>
<h2 id="错误处理"><a href="#错误处理" class="headerlink" title="错误处理"></a>错误处理</h2><p>在程序运行的过程中，如果发生了错误，可以事先约定返回一个错误代码，这样，就可以知道是否有错，以及出错的原因。在操作系统提供的调用中，返回错误码非常常见。比如打开文件的函数<code>open()</code>，成功时返回文件描述符（就是一个整数），出错时返回<code>-1</code>。</p>
<p>用错误码来表示是否出错十分不便，因为函数本身应该返回的正常结果和错误码混在一起，造成调用者必须用大量的代码来判断是否出错：</p>
<figure class="highlight plain"><table><tr><td class="gutter"><pre><span class="line">1</span><br><span class="line">2</span><br><span class="line">3</span><br><span class="line">4</span><br><span class="line">5</span><br><span class="line">6</span><br><span class="line">7</span><br><span class="line">8</span><br><span class="line">9</span><br><span class="line">10</span><br><span class="line">11</span><br><span class="line">12</span><br><span class="line">13</span><br></pre></td><td class="code"><pre><span class="line">def foo():</span><br><span class="line">    r = some_function()</span><br><span class="line">    if r==(-1):</span><br><span class="line">        return (-1)</span><br><span class="line">    # do something</span><br><span class="line">    return r</span><br><span class="line"></span><br><span class="line">def bar():</span><br><span class="line">    r = foo()</span><br><span class="line">    if r==(-1):</span><br><span class="line">        print(&apos;Error&apos;)</span><br><span class="line">    else:</span><br><span class="line">        pass</span><br></pre></td></tr></table></figure>
<p>一旦出错，还要一级一级上报，直到某个函数可以处理该错误（比如，给用户输出一个错误信息）。</p>
<p>所以高级语言通常都内置了一套<code>try...except...finally...</code>的错误处理机制，Python也不例外。</p>
<h3 id="try"><a href="#try" class="headerlink" title="try"></a>try</h3><p>让我们用一个例子来看看<code>try</code>的机制：</p>
<figure class="highlight plain"><table><tr><td class="gutter"><pre><span class="line">1</span><br><span class="line">2</span><br><span class="line">3</span><br><span class="line">4</span><br><span class="line">5</span><br><span class="line">6</span><br><span class="line">7</span><br><span class="line">8</span><br><span class="line">9</span><br></pre></td><td class="code"><pre><span class="line">try:</span><br><span class="line">    print(&apos;try...&apos;)</span><br><span class="line">    r = 10 / 0</span><br><span class="line">    print(&apos;result:&apos;, r)</span><br><span class="line">except ZeroDivisionError as e:</span><br><span class="line">    print(&apos;except:&apos;, e)</span><br><span class="line">finally:</span><br><span class="line">    print(&apos;finally...&apos;)</span><br><span class="line">print(&apos;END&apos;)</span><br></pre></td></tr></table></figure>
<p>当我们认为某些代码可能会出错时，就可以用<code>try</code>来运行这段代码，如果执行出错，则后续代码不会继续执行，而是直接跳转至错误处理代码，即<code>except</code>语句块，执行完<code>except</code>后，如果有<code>finally</code>语句块，则执行<code>finally</code>语句块，至此，执行完毕。</p>
<p>上面的代码在计算<code>10 / 0</code>时会产生一个除法运算错误：</p>
<figure class="highlight plain"><table><tr><td class="gutter"><pre><span class="line">1</span><br><span class="line">2</span><br><span class="line">3</span><br><span class="line">4</span><br></pre></td><td class="code"><pre><span class="line">try...</span><br><span class="line">except: division by zero</span><br><span class="line">finally...</span><br><span class="line">END</span><br></pre></td></tr></table></figure>
<p>从输出可以看到，当错误发生时，后续语句<code>print(&#39;result:&#39;, r)</code>不会被执行，<code>except</code>由于捕获到<code>ZeroDivisionError</code>，因此被执行。最后，<code>finally</code>语句被执行。然后，程序继续按照流程往下走。</p>
<p>如果把除数<code>0</code>改成<code>2</code>，则执行结果如下：</p>
<figure class="highlight plain"><table><tr><td class="gutter"><pre><span class="line">1</span><br><span class="line">2</span><br><span class="line">3</span><br><span class="line">4</span><br></pre></td><td class="code"><pre><span class="line">try...</span><br><span class="line">result: 5</span><br><span class="line">finally...</span><br><span class="line">END</span><br></pre></td></tr></table></figure>
<p>由于没有错误发生，所以<code>except</code>语句块不会被执行，但是<code>finally</code>如果有，则一定会被执行（可以没有<code>finally</code>语句）。</p>
<p>你还可以猜测，错误应该有很多种类，如果发生了不同类型的错误，应该由不同的<code>except</code>语句块处理。没错，可以有多个<code>except</code>来捕获不同类型的错误：</p>
<figure class="highlight plain"><table><tr><td class="gutter"><pre><span class="line">1</span><br><span class="line">2</span><br><span class="line">3</span><br><span class="line">4</span><br><span class="line">5</span><br><span class="line">6</span><br><span class="line">7</span><br><span class="line">8</span><br><span class="line">9</span><br><span class="line">10</span><br><span class="line">11</span><br></pre></td><td class="code"><pre><span class="line">try:</span><br><span class="line">    print(&apos;try...&apos;)</span><br><span class="line">    r = 10 / int(&apos;a&apos;)</span><br><span class="line">    print(&apos;result:&apos;, r)</span><br><span class="line">except ValueError as e:</span><br><span class="line">    print(&apos;ValueError:&apos;, e)</span><br><span class="line">except ZeroDivisionError as e:</span><br><span class="line">    print(&apos;ZeroDivisionError:&apos;, e)</span><br><span class="line">finally:</span><br><span class="line">    print(&apos;finally...&apos;)</span><br><span class="line">print(&apos;END&apos;)</span><br></pre></td></tr></table></figure>
<p><code>int()</code>函数可能会抛出<code>ValueError</code>，所以我们用一个<code>except</code>捕获<code>ValueError</code>，用另一个<code>except</code>捕获<code>ZeroDivisionError</code>。</p>
<p>此外，如果没有错误发生，可以在<code>except</code>语句块后面加一个<code>else</code>，当没有错误发生时，会自动执行<code>else</code>语句：</p>
<figure class="highlight plain"><table><tr><td class="gutter"><pre><span class="line">1</span><br><span class="line">2</span><br><span class="line">3</span><br><span class="line">4</span><br><span class="line">5</span><br><span class="line">6</span><br><span class="line">7</span><br><span class="line">8</span><br><span class="line">9</span><br><span class="line">10</span><br><span class="line">11</span><br><span class="line">12</span><br><span class="line">13</span><br></pre></td><td class="code"><pre><span class="line">try:</span><br><span class="line">    print(&apos;try...&apos;)</span><br><span class="line">    r = 10 / int(&apos;2&apos;)</span><br><span class="line">    print(&apos;result:&apos;, r)</span><br><span class="line">except ValueError as e:</span><br><span class="line">    print(&apos;ValueError:&apos;, e)</span><br><span class="line">except ZeroDivisionError as e:</span><br><span class="line">    print(&apos;ZeroDivisionError:&apos;, e)</span><br><span class="line">else:</span><br><span class="line">    print(&apos;no error!&apos;)</span><br><span class="line">finally:</span><br><span class="line">    print(&apos;finally...&apos;)</span><br><span class="line">print(&apos;END&apos;)</span><br></pre></td></tr></table></figure>
<p>Python的错误其实也是class，所有的错误类型都继承自<code>BaseException</code>，所以在使用<code>except</code>时需要注意的是，它不但捕获该类型的错误，还把其子类也“一网打尽”。比如：</p>
<figure class="highlight plain"><table><tr><td class="gutter"><pre><span class="line">1</span><br><span class="line">2</span><br><span class="line">3</span><br><span class="line">4</span><br><span class="line">5</span><br><span class="line">6</span><br></pre></td><td class="code"><pre><span class="line">try:</span><br><span class="line">    foo()</span><br><span class="line">except ValueError as e:</span><br><span class="line">    print(&apos;ValueError&apos;)</span><br><span class="line">except UnicodeError as e:</span><br><span class="line">    print(&apos;UnicodeError&apos;)</span><br></pre></td></tr></table></figure>
<p>第二个<code>except</code>永远也捕获不到<code>UnicodeError</code>，因为<code>UnicodeError</code>是<code>ValueError</code>的子类，如果有，也被第一个<code>except</code>给捕获了。</p>
<p>Python所有的错误都是从<code>BaseException</code>类派生的，常见的错误类型和继承关系看这里：</p>
<p><a href="https://docs.python.org/3/library/exceptions.html#exception-hierarchy" target="_blank" rel="noopener">https://docs.python.org/3/library/exceptions.html#exception-hierarchy</a></p>
<p>使用<code>try...except</code>捕获错误还有一个巨大的好处，就是可以跨越多层调用，比如函数<code>main()</code>调用<code>foo()</code>，<code>foo()</code>调用<code>bar()</code>，结果<code>bar()</code>出错了，这时，只要<code>main()</code>捕获到了，就可以处理：</p>
<figure class="highlight plain"><table><tr><td class="gutter"><pre><span class="line">1</span><br><span class="line">2</span><br><span class="line">3</span><br><span class="line">4</span><br><span class="line">5</span><br><span class="line">6</span><br><span class="line">7</span><br><span class="line">8</span><br><span class="line">9</span><br><span class="line">10</span><br><span class="line">11</span><br><span class="line">12</span><br><span class="line">13</span><br></pre></td><td class="code"><pre><span class="line">def foo(s):</span><br><span class="line">    return 10 / int(s)</span><br><span class="line"></span><br><span class="line">def bar(s):</span><br><span class="line">    return foo(s) * 2</span><br><span class="line"></span><br><span class="line">def main():</span><br><span class="line">    try:</span><br><span class="line">        bar(&apos;0&apos;)</span><br><span class="line">    except Exception as e:</span><br><span class="line">        print(&apos;Error:&apos;, e)</span><br><span class="line">    finally:</span><br><span class="line">        print(&apos;finally...&apos;)</span><br></pre></td></tr></table></figure>
<p>也就是说，不需要在每个可能出错的地方去捕获错误，只要在合适的层次去捕获错误就可以了。这样一来，就大大减少了写<code>try...except...finally</code>的麻烦。</p>
<h3 id="调用栈"><a href="#调用栈" class="headerlink" title="调用栈"></a>调用栈</h3><p>如果错误没有被捕获，它就会一直往上抛，最后被Python解释器捕获，打印一个错误信息，然后程序退出。来看看<code>err.py</code>：</p>
<figure class="highlight plain"><table><tr><td class="gutter"><pre><span class="line">1</span><br><span class="line">2</span><br><span class="line">3</span><br><span class="line">4</span><br><span class="line">5</span><br><span class="line">6</span><br><span class="line">7</span><br><span class="line">8</span><br><span class="line">9</span><br><span class="line">10</span><br><span class="line">11</span><br></pre></td><td class="code"><pre><span class="line"># err.py:</span><br><span class="line">def foo(s):</span><br><span class="line">    return 10 / int(s)</span><br><span class="line"></span><br><span class="line">def bar(s):</span><br><span class="line">    return foo(s) * 2</span><br><span class="line"></span><br><span class="line">def main():</span><br><span class="line">    bar(&apos;0&apos;)</span><br><span class="line"></span><br><span class="line">main()</span><br></pre></td></tr></table></figure>
<p>执行，结果如下：</p>
<figure class="highlight plain"><table><tr><td class="gutter"><pre><span class="line">1</span><br><span class="line">2</span><br><span class="line">3</span><br><span class="line">4</span><br><span class="line">5</span><br><span class="line">6</span><br><span class="line">7</span><br><span class="line">8</span><br><span class="line">9</span><br><span class="line">10</span><br><span class="line">11</span><br></pre></td><td class="code"><pre><span class="line">$ python3 err.py</span><br><span class="line">Traceback (most recent call last):</span><br><span class="line">  File &quot;err.py&quot;, line 11, in &lt;module&gt;</span><br><span class="line">    main()</span><br><span class="line">  File &quot;err.py&quot;, line 9, in main</span><br><span class="line">    bar(&apos;0&apos;)</span><br><span class="line">  File &quot;err.py&quot;, line 6, in bar</span><br><span class="line">    return foo(s) * 2</span><br><span class="line">  File &quot;err.py&quot;, line 3, in foo</span><br><span class="line">    return 10 / int(s)</span><br><span class="line">ZeroDivisionError: division by zero</span><br></pre></td></tr></table></figure>
<p>出错并不可怕，可怕的是不知道哪里出错了。解读错误信息是定位错误的关键。我们从上往下可以看到整个错误的调用函数链：</p>
<p>错误信息第1行：</p>
<figure class="highlight plain"><table><tr><td class="gutter"><pre><span class="line">1</span><br></pre></td><td class="code"><pre><span class="line">Traceback (most recent call last):</span><br></pre></td></tr></table></figure>
<p>告诉我们这是错误的跟踪信息。</p>
<p>第2~3行：</p>
<figure class="highlight plain"><table><tr><td class="gutter"><pre><span class="line">1</span><br><span class="line">2</span><br></pre></td><td class="code"><pre><span class="line">File &quot;err.py&quot;, line 11, in &lt;module&gt;</span><br><span class="line">  main()</span><br></pre></td></tr></table></figure>
<p>调用<code>main()</code>出错了，在代码文件<code>err.py</code>的第11行代码，但原因是第9行：</p>
<figure class="highlight plain"><table><tr><td class="gutter"><pre><span class="line">1</span><br><span class="line">2</span><br></pre></td><td class="code"><pre><span class="line">File &quot;err.py&quot;, line 9, in main</span><br><span class="line">  bar(&apos;0&apos;)</span><br></pre></td></tr></table></figure>
<p>调用<code>bar(&#39;0&#39;)</code>出错了，在代码文件<code>err.py</code>的第9行代码，但原因是第6行：</p>
<figure class="highlight plain"><table><tr><td class="gutter"><pre><span class="line">1</span><br><span class="line">2</span><br></pre></td><td class="code"><pre><span class="line">File &quot;err.py&quot;, line 6, in bar</span><br><span class="line">  return foo(s) * 2</span><br></pre></td></tr></table></figure>
<p>原因是<code>return foo(s) * 2</code>这个语句出错了，但这还不是最终原因，继续往下看：</p>
<figure class="highlight plain"><table><tr><td class="gutter"><pre><span class="line">1</span><br><span class="line">2</span><br></pre></td><td class="code"><pre><span class="line">File &quot;err.py&quot;, line 3, in foo</span><br><span class="line">  return 10 / int(s)</span><br></pre></td></tr></table></figure>
<p>原因是<code>return 10 / int(s)</code>这个语句出错了，这是错误产生的源头，因为下面打印了：</p>
<figure class="highlight plain"><table><tr><td class="gutter"><pre><span class="line">1</span><br></pre></td><td class="code"><pre><span class="line">ZeroDivisionError: integer division or modulo by zero</span><br></pre></td></tr></table></figure>
<p>根据错误类型<code>ZeroDivisionError</code>，我们判断，<code>int(s)</code>本身并没有出错，但是<code>int(s)</code>返回<code>0</code>，在计算<code>10 / 0</code>时出错，至此，找到错误源头。</p>
<p>** 出错的时候，一定要分析错误的调用栈信息，才能定位错误的位置。</p>
<h3 id="记录错误"><a href="#记录错误" class="headerlink" title="记录错误"></a>记录错误</h3><p>如果不捕获错误，自然可以让Python解释器来打印出错误堆栈，但程序也被结束了。既然我们能捕获错误，就可以把错误堆栈打印出来，然后分析错误原因，同时，让程序继续执行下去。</p>
<p>Python内置的<code>logging</code>模块可以非常容易地记录错误信息：</p>
<figure class="highlight plain"><table><tr><td class="gutter"><pre><span class="line">1</span><br><span class="line">2</span><br><span class="line">3</span><br><span class="line">4</span><br><span class="line">5</span><br><span class="line">6</span><br><span class="line">7</span><br><span class="line">8</span><br><span class="line">9</span><br><span class="line">10</span><br><span class="line">11</span><br><span class="line">12</span><br><span class="line">13</span><br><span class="line">14</span><br><span class="line">15</span><br><span class="line">16</span><br><span class="line">17</span><br><span class="line">18</span><br></pre></td><td class="code"><pre><span class="line"># err_logging.py</span><br><span class="line"></span><br><span class="line">import logging</span><br><span class="line"></span><br><span class="line">def foo(s):</span><br><span class="line">    return 10 / int(s)</span><br><span class="line"></span><br><span class="line">def bar(s):</span><br><span class="line">    return foo(s) * 2</span><br><span class="line"></span><br><span class="line">def main():</span><br><span class="line">    try:</span><br><span class="line">        bar(&apos;0&apos;)</span><br><span class="line">    except Exception as e:</span><br><span class="line">        logging.exception(e)</span><br><span class="line"></span><br><span class="line">main()</span><br><span class="line">print(&apos;END&apos;)</span><br></pre></td></tr></table></figure>
<p>同样是出错，但程序打印完错误信息后会继续执行，并正常退出：</p>
<figure class="highlight plain"><table><tr><td class="gutter"><pre><span class="line">1</span><br><span class="line">2</span><br><span class="line">3</span><br><span class="line">4</span><br><span class="line">5</span><br><span class="line">6</span><br><span class="line">7</span><br><span class="line">8</span><br><span class="line">9</span><br><span class="line">10</span><br><span class="line">11</span><br></pre></td><td class="code"><pre><span class="line">$ python3 err_logging.py</span><br><span class="line">ERROR:root:division by zero</span><br><span class="line">Traceback (most recent call last):</span><br><span class="line">  File &quot;err_logging.py&quot;, line 13, in main</span><br><span class="line">    bar(&apos;0&apos;)</span><br><span class="line">  File &quot;err_logging.py&quot;, line 9, in bar</span><br><span class="line">    return foo(s) * 2</span><br><span class="line">  File &quot;err_logging.py&quot;, line 6, in foo</span><br><span class="line">    return 10 / int(s)</span><br><span class="line">ZeroDivisionError: division by zero</span><br><span class="line">END</span><br></pre></td></tr></table></figure>
<p>通过配置，<code>logging</code>还可以把错误记录到日志文件里，方便事后排查。</p>
<h3 id="抛出错误"><a href="#抛出错误" class="headerlink" title="抛出错误"></a>抛出错误</h3><p>因为错误是class，捕获一个错误就是捕获到该class的一个实例。因此，错误并不是凭空产生的，而是有意创建并抛出的。Python的内置函数会抛出很多类型的错误，我们自己编写的函数也可以抛出错误。</p>
<p>如果要抛出错误，首先根据需要，可以定义一个错误的class，选择好继承关系，然后，用<code>raise</code>语句抛出一个错误的实例：</p>
<figure class="highlight plain"><table><tr><td class="gutter"><pre><span class="line">1</span><br><span class="line">2</span><br><span class="line">3</span><br><span class="line">4</span><br><span class="line">5</span><br><span class="line">6</span><br><span class="line">7</span><br><span class="line">8</span><br><span class="line">9</span><br><span class="line">10</span><br><span class="line">11</span><br></pre></td><td class="code"><pre><span class="line"># err_raise.py</span><br><span class="line">class FooError(ValueError):</span><br><span class="line">    pass</span><br><span class="line"></span><br><span class="line">def foo(s):</span><br><span class="line">    n = int(s)</span><br><span class="line">    if n==0:</span><br><span class="line">        raise FooError(&apos;invalid value: %s&apos; % s)</span><br><span class="line">    return 10 / n</span><br><span class="line"></span><br><span class="line">foo(&apos;0&apos;)</span><br></pre></td></tr></table></figure>
<p>执行，可以最后跟踪到我们自己定义的错误：</p>
<figure class="highlight plain"><table><tr><td class="gutter"><pre><span class="line">1</span><br><span class="line">2</span><br><span class="line">3</span><br><span class="line">4</span><br><span class="line">5</span><br><span class="line">6</span><br><span class="line">7</span><br></pre></td><td class="code"><pre><span class="line">$ python3 err_raise.py </span><br><span class="line">Traceback (most recent call last):</span><br><span class="line">  File &quot;err_throw.py&quot;, line 11, in &lt;module&gt;</span><br><span class="line">    foo(&apos;0&apos;)</span><br><span class="line">  File &quot;err_throw.py&quot;, line 8, in foo</span><br><span class="line">    raise FooError(&apos;invalid value: %s&apos; % s)</span><br><span class="line">__main__.FooError: invalid value: 0</span><br></pre></td></tr></table></figure>
<p>只有在必要的时候才定义我们自己的错误类型。如果可以选择Python已有的内置的错误类型（比如<code>ValueError</code>，<code>TypeError</code>），尽量使用Python内置的错误类型。</p>
<p>最后，我们来看另一种错误处理的方式：</p>
<figure class="highlight plain"><table><tr><td class="gutter"><pre><span class="line">1</span><br><span class="line">2</span><br><span class="line">3</span><br><span class="line">4</span><br><span class="line">5</span><br><span class="line">6</span><br><span class="line">7</span><br><span class="line">8</span><br><span class="line">9</span><br><span class="line">10</span><br><span class="line">11</span><br><span class="line">12</span><br><span class="line">13</span><br><span class="line">14</span><br><span class="line">15</span><br><span class="line">16</span><br></pre></td><td class="code"><pre><span class="line"># err_reraise.py</span><br><span class="line"></span><br><span class="line">def foo(s):</span><br><span class="line">    n = int(s)</span><br><span class="line">    if n==0:</span><br><span class="line">        raise ValueError(&apos;invalid value: %s&apos; % s)</span><br><span class="line">    return 10 / n</span><br><span class="line"></span><br><span class="line">def bar():</span><br><span class="line">    try:</span><br><span class="line">        foo(&apos;0&apos;)</span><br><span class="line">    except ValueError as e:</span><br><span class="line">        print(&apos;ValueError!&apos;)</span><br><span class="line">        raise</span><br><span class="line"></span><br><span class="line">bar()</span><br></pre></td></tr></table></figure>
<p>在<code>bar()</code>函数中，我们明明已经捕获了错误，但是，打印一个<code>ValueError!</code>后，又把错误通过<code>raise</code>语句抛出去了，这不有病么？</p>
<p>其实这种错误处理方式不但没病，而且相当常见。捕获错误目的只是记录一下，便于后续追踪。但是，由于当前函数不知道应该怎么处理该错误，所以，最恰当的方式是继续往上抛，让顶层调用者去处理。好比一个员工处理不了一个问题时，就把问题抛给他的老板，如果他的老板也处理不了，就一直往上抛，最终会抛给CEO去处理。</p>
<p><code>raise</code>语句如果不带参数，就会把当前错误原样抛出。此外，在<code>except</code>中<code>raise</code>一个Error，还可以把一种类型的错误转化成另一种类型：</p>
<figure class="highlight plain"><table><tr><td class="gutter"><pre><span class="line">1</span><br><span class="line">2</span><br><span class="line">3</span><br><span class="line">4</span><br></pre></td><td class="code"><pre><span class="line">try:</span><br><span class="line">    10 / 0</span><br><span class="line">except ZeroDivisionError:</span><br><span class="line">    raise ValueError(&apos;input error!&apos;)</span><br></pre></td></tr></table></figure>
<p>只要是合理的转换逻辑就可以，但是，决不应该把一个<code>IOError</code>转换成毫不相干的<code>ValueError</code>。</p>

  </div>
</article>

    <div class="blog-post-comments">
        <div id="disqus_thread">
            <noscript>加载评论需要在浏览器启用 JavaScript 脚本支持。</noscript>
        </div>
    </div>



        
          <div id="footer-post-container">
  <div id="footer-post">

    <div id="nav-footer" style="display: none">
      <ul>
        
      </ul>
    </div>

    <div id="toc-footer" style="display: none">
      <ol class="toc"><li class="toc-item toc-level-1"><a class="toc-link" href="#错误、调试和测试"><span class="toc-number">1.</span> <span class="toc-text">错误、调试和测试</span></a><ol class="toc-child"><li class="toc-item toc-level-2"><a class="toc-link" href="#错误处理"><span class="toc-number">1.1.</span> <span class="toc-text">错误处理</span></a><ol class="toc-child"><li class="toc-item toc-level-3"><a class="toc-link" href="#try"><span class="toc-number">1.1.1.</span> <span class="toc-text">try</span></a></li><li class="toc-item toc-level-3"><a class="toc-link" href="#调用栈"><span class="toc-number">1.1.2.</span> <span class="toc-text">调用栈</span></a></li><li class="toc-item toc-level-3"><a class="toc-link" href="#记录错误"><span class="toc-number">1.1.3.</span> <span class="toc-text">记录错误</span></a></li><li class="toc-item toc-level-3"><a class="toc-link" href="#抛出错误"><span class="toc-number">1.1.4.</span> <span class="toc-text">抛出错误</span></a></li></ol></li></ol></li></ol>
    </div>

    <div id="share-footer" style="display: none">
      <ul>
  <li><a class="icon" href="http://www.facebook.com/sharer.php?u=http://yoursite.com/2018/02/22/Python错误调试及IO编程.html"><i class="fab fa-facebook fa-lg" aria-hidden="true"></i></a></li>
  <li><a class="icon" href="https://twitter.com/share?url=http://yoursite.com/2018/02/22/Python错误调试及IO编程.html&text=Python错误调试及IO编程"><i class="fab fa-twitter fa-lg" aria-hidden="true"></i></a></li>
  <li><a class="icon" href="http://www.linkedin.com/shareArticle?url=http://yoursite.com/2018/02/22/Python错误调试及IO编程.html&title=Python错误调试及IO编程"><i class="fab fa-linkedin fa-lg" aria-hidden="true"></i></a></li>
  <li><a class="icon" href="https://pinterest.com/pin/create/bookmarklet/?url=http://yoursite.com/2018/02/22/Python错误调试及IO编程.html&is_video=false&description=Python错误调试及IO编程"><i class="fab fa-pinterest fa-lg" aria-hidden="true"></i></a></li>
  <li><a class="icon" href="mailto:?subject=Python错误调试及IO编程&body=Check out this article: http://yoursite.com/2018/02/22/Python错误调试及IO编程.html"><i class="fas fa-envelope fa-lg" aria-hidden="true"></i></a></li>
  <li><a class="icon" href="https://getpocket.com/save?url=http://yoursite.com/2018/02/22/Python错误调试及IO编程.html&title=Python错误调试及IO编程"><i class="fab fa-get-pocket fa-lg" aria-hidden="true"></i></a></li>
  <li><a class="icon" href="http://reddit.com/submit?url=http://yoursite.com/2018/02/22/Python错误调试及IO编程.html&title=Python错误调试及IO编程"><i class="fab fa-reddit fa-lg" aria-hidden="true"></i></a></li>
  <li><a class="icon" href="http://www.stumbleupon.com/submit?url=http://yoursite.com/2018/02/22/Python错误调试及IO编程.html&title=Python错误调试及IO编程"><i class="fab fa-stumbleupon fa-lg" aria-hidden="true"></i></a></li>
  <li><a class="icon" href="http://digg.com/submit?url=http://yoursite.com/2018/02/22/Python错误调试及IO编程.html&title=Python错误调试及IO编程"><i class="fab fa-digg fa-lg" aria-hidden="true"></i></a></li>
  <li><a class="icon" href="http://www.tumblr.com/share/link?url=http://yoursite.com/2018/02/22/Python错误调试及IO编程.html&name=Python错误调试及IO编程&description="><i class="fab fa-tumblr fa-lg" aria-hidden="true"></i></a></li>
</ul>

    </div>

    <div id="actions-footer">
        <a id="menu" class="icon" href="#" onclick="$('#nav-footer').toggle();return false;"><i class="fas fa-bars fa-lg" aria-hidden="true"></i> 菜单</a>
        <a id="toc" class="icon" href="#" onclick="$('#toc-footer').toggle();return false;"><i class="fas fa-list fa-lg" aria-hidden="true"></i> 目录</a>
        <li id="home"><a class="icon" href=/><i class="fa fa-list fa-lg" aria-hidden="true"></i> HOME</a></li>
        <a id="top" style="display:none" class="icon" href="#" onclick="$('html, body').animate({ scrollTop: 0 }, 'fast');"><i class="fas fa-chevron-up fa-lg" aria-hidden="true"></i> 返回顶部</a>
    </div>

  </div>
</div>

        
        <footer id="footer">
  <div class="footer-left">
    Copyright &copy; 2018 BirdMichael
  </div>
  <div class="footer-right">
    <nav>
      <ul>
        
      </ul>
    </nav>
  </div>
</footer>

    </div>
</body>
</html>
<!-- styles -->
<link rel="stylesheet" href="/lib/font-awesome/css/all.min.css">
<link rel="stylesheet" href="/lib/justified-gallery/css/justifiedGallery.min.css">

<!-- jquery -->
<script src="/lib/jquery/jquery.min.js"></script>
<script src="/lib/justified-gallery/js/jquery.justifiedGallery.min.js"></script>
<script src="/js/main.js"></script>
<!-- search -->

<!-- Google Analytics -->

<!-- Baidu Analytics -->

<!-- Disqus Comments -->

    <script type="text/javascript">
        var disqus_shortname = 'birdmichael';

        (function(){
            var dsq = document.createElement('script');
            dsq.type = 'text/javascript';
            dsq.async = true;
            dsq.src = '//' + disqus_shortname + '.disqus.com/embed.js';
            (document.getElementsByTagName('head')[0] || document.getElementsByTagName('body')[0]).appendChild(dsq);
        }());
    </script>


